2022-11-14 10:42:46,233 ERROR: Exception on / [GET] [in C:\Users\leonv\Documents\Transporte\venv\lib\site-packages\flask\app.py:1891]
Traceback (most recent call last):
  File "C:\Users\leonv\Documents\Transporte\venv\lib\site-packages\flask\app.py", line 2447, in wsgi_app
    response = self.full_dispatch_request()
  File "C:\Users\leonv\Documents\Transporte\venv\lib\site-packages\flask\app.py", line 1952, in full_dispatch_request
    rv = self.handle_user_exception(e)
  File "C:\Users\leonv\Documents\Transporte\venv\lib\site-packages\flask\app.py", line 1821, in handle_user_exception
    reraise(exc_type, exc_value, tb)
  File "C:\Users\leonv\Documents\Transporte\venv\lib\site-packages\flask\_compat.py", line 39, in reraise
    raise value
  File "C:\Users\leonv\Documents\Transporte\venv\lib\site-packages\flask\app.py", line 1950, in full_dispatch_request
    rv = self.dispatch_request()
  File "C:\Users\leonv\Documents\Transporte\venv\lib\site-packages\flask\app.py", line 1936, in dispatch_request
    return self.view_functions[rule.endpoint](**req.view_args)
  File "C:\Users\leonv\Documents\Transporte\venv\lib\site-packages\flask_login\utils.py", line 272, in decorated_view
    return func(*args, **kwargs)
  File "C:\Users\leonv\Documents\Transporte\app\main\routes.py", line 27, in index
    if usuario.aluno.respondido:
AttributeError: 'InstrumentedList' object has no attribute 'respondido'
2022-11-14 10:47:47,759 INFO: Transporte inicialização [in C:\Users\leonv\Documents\Transporte\app\__init__.py:84]
2022-11-14 10:47:52,775 ERROR: Exception on /index [GET] [in C:\Users\leonv\Documents\Transporte\venv\lib\site-packages\flask\app.py:1891]
Traceback (most recent call last):
  File "C:\Users\leonv\Documents\Transporte\venv\lib\site-packages\flask\app.py", line 2447, in wsgi_app
    response = self.full_dispatch_request()
  File "C:\Users\leonv\Documents\Transporte\venv\lib\site-packages\flask\app.py", line 1952, in full_dispatch_request
    rv = self.handle_user_exception(e)
  File "C:\Users\leonv\Documents\Transporte\venv\lib\site-packages\flask\app.py", line 1821, in handle_user_exception
    reraise(exc_type, exc_value, tb)
  File "C:\Users\leonv\Documents\Transporte\venv\lib\site-packages\flask\_compat.py", line 39, in reraise
    raise value
  File "C:\Users\leonv\Documents\Transporte\venv\lib\site-packages\flask\app.py", line 1950, in full_dispatch_request
    rv = self.dispatch_request()
  File "C:\Users\leonv\Documents\Transporte\venv\lib\site-packages\flask\app.py", line 1936, in dispatch_request
    return self.view_functions[rule.endpoint](**req.view_args)
  File "C:\Users\leonv\Documents\Transporte\venv\lib\site-packages\flask_login\utils.py", line 272, in decorated_view
    return func(*args, **kwargs)
  File "C:\Users\leonv\Documents\Transporte\app\main\routes.py", line 27, in index
    if usuario.aluno.respondido:
AttributeError: 'InstrumentedList' object has no attribute 'respondido'
2022-11-14 10:49:44,335 INFO: Transporte inicialização [in C:\Users\leonv\Documents\Transporte\app\__init__.py:84]
2022-11-14 10:49:44,652 ERROR: Exception on /index [GET] [in C:\Users\leonv\Documents\Transporte\venv\lib\site-packages\flask\app.py:1891]
Traceback (most recent call last):
  File "C:\Users\leonv\Documents\Transporte\venv\lib\site-packages\flask\app.py", line 2447, in wsgi_app
    response = self.full_dispatch_request()
  File "C:\Users\leonv\Documents\Transporte\venv\lib\site-packages\flask\app.py", line 1952, in full_dispatch_request
    rv = self.handle_user_exception(e)
  File "C:\Users\leonv\Documents\Transporte\venv\lib\site-packages\flask\app.py", line 1821, in handle_user_exception
    reraise(exc_type, exc_value, tb)
  File "C:\Users\leonv\Documents\Transporte\venv\lib\site-packages\flask\_compat.py", line 39, in reraise
    raise value
  File "C:\Users\leonv\Documents\Transporte\venv\lib\site-packages\flask\app.py", line 1950, in full_dispatch_request
    rv = self.dispatch_request()
  File "C:\Users\leonv\Documents\Transporte\venv\lib\site-packages\flask\app.py", line 1936, in dispatch_request
    return self.view_functions[rule.endpoint](**req.view_args)
  File "C:\Users\leonv\Documents\Transporte\venv\lib\site-packages\flask_login\utils.py", line 272, in decorated_view
    return func(*args, **kwargs)
  File "C:\Users\leonv\Documents\Transporte\app\main\routes.py", line 27, in index
    if usuario.aluno.respondido:
AttributeError: 'InstrumentedList' object has no attribute 'respondido'
2022-11-14 10:50:32,066 INFO: Transporte inicialização [in C:\Users\leonv\Documents\Transporte\app\__init__.py:84]
2022-11-14 10:50:34,855 ERROR: Exception on /index [GET] [in C:\Users\leonv\Documents\Transporte\venv\lib\site-packages\flask\app.py:1891]
Traceback (most recent call last):
  File "C:\Users\leonv\Documents\Transporte\venv\lib\site-packages\flask\app.py", line 2447, in wsgi_app
    response = self.full_dispatch_request()
  File "C:\Users\leonv\Documents\Transporte\venv\lib\site-packages\flask\app.py", line 1952, in full_dispatch_request
    rv = self.handle_user_exception(e)
  File "C:\Users\leonv\Documents\Transporte\venv\lib\site-packages\flask\app.py", line 1821, in handle_user_exception
    reraise(exc_type, exc_value, tb)
  File "C:\Users\leonv\Documents\Transporte\venv\lib\site-packages\flask\_compat.py", line 39, in reraise
    raise value
  File "C:\Users\leonv\Documents\Transporte\venv\lib\site-packages\flask\app.py", line 1950, in full_dispatch_request
    rv = self.dispatch_request()
  File "C:\Users\leonv\Documents\Transporte\venv\lib\site-packages\flask\app.py", line 1936, in dispatch_request
    return self.view_functions[rule.endpoint](**req.view_args)
  File "C:\Users\leonv\Documents\Transporte\venv\lib\site-packages\flask_login\utils.py", line 272, in decorated_view
    return func(*args, **kwargs)
  File "C:\Users\leonv\Documents\Transporte\app\main\routes.py", line 28, in index
    if usuario.aluno.respondido:
AttributeError: 'InstrumentedList' object has no attribute 'respondido'
2022-11-14 10:52:27,860 INFO: Transporte inicialização [in C:\Users\leonv\Documents\Transporte\app\__init__.py:84]
2022-11-14 10:52:30,688 ERROR: Exception on /index [GET] [in C:\Users\leonv\Documents\Transporte\venv\lib\site-packages\flask\app.py:1891]
Traceback (most recent call last):
  File "C:\Users\leonv\Documents\Transporte\venv\lib\site-packages\flask\app.py", line 2447, in wsgi_app
    response = self.full_dispatch_request()
  File "C:\Users\leonv\Documents\Transporte\venv\lib\site-packages\flask\app.py", line 1952, in full_dispatch_request
    rv = self.handle_user_exception(e)
  File "C:\Users\leonv\Documents\Transporte\venv\lib\site-packages\flask\app.py", line 1821, in handle_user_exception
    reraise(exc_type, exc_value, tb)
  File "C:\Users\leonv\Documents\Transporte\venv\lib\site-packages\flask\_compat.py", line 39, in reraise
    raise value
  File "C:\Users\leonv\Documents\Transporte\venv\lib\site-packages\flask\app.py", line 1950, in full_dispatch_request
    rv = self.dispatch_request()
  File "C:\Users\leonv\Documents\Transporte\venv\lib\site-packages\flask\app.py", line 1936, in dispatch_request
    return self.view_functions[rule.endpoint](**req.view_args)
  File "C:\Users\leonv\Documents\Transporte\venv\lib\site-packages\flask_login\utils.py", line 272, in decorated_view
    return func(*args, **kwargs)
  File "C:\Users\leonv\Documents\Transporte\app\main\routes.py", line 28, in index
    if usuario.aluno.respondido:
AttributeError: 'InstrumentedList' object has no attribute 'respondido'
2022-11-14 10:53:49,132 INFO: Transporte inicialização [in C:\Users\leonv\Documents\Transporte\app\__init__.py:84]
2022-11-14 10:53:51,691 ERROR: Exception on /index [GET] [in C:\Users\leonv\Documents\Transporte\venv\lib\site-packages\flask\app.py:1891]
Traceback (most recent call last):
  File "C:\Users\leonv\Documents\Transporte\venv\lib\site-packages\flask\app.py", line 2447, in wsgi_app
    response = self.full_dispatch_request()
  File "C:\Users\leonv\Documents\Transporte\venv\lib\site-packages\flask\app.py", line 1952, in full_dispatch_request
    rv = self.handle_user_exception(e)
  File "C:\Users\leonv\Documents\Transporte\venv\lib\site-packages\flask\app.py", line 1821, in handle_user_exception
    reraise(exc_type, exc_value, tb)
  File "C:\Users\leonv\Documents\Transporte\venv\lib\site-packages\flask\_compat.py", line 39, in reraise
    raise value
  File "C:\Users\leonv\Documents\Transporte\venv\lib\site-packages\flask\app.py", line 1950, in full_dispatch_request
    rv = self.dispatch_request()
  File "C:\Users\leonv\Documents\Transporte\venv\lib\site-packages\flask\app.py", line 1936, in dispatch_request
    return self.view_functions[rule.endpoint](**req.view_args)
  File "C:\Users\leonv\Documents\Transporte\venv\lib\site-packages\flask_login\utils.py", line 272, in decorated_view
    return func(*args, **kwargs)
  File "C:\Users\leonv\Documents\Transporte\app\main\routes.py", line 28, in index
    if usuario.usuario_aluno.respondido:
  File "C:\Users\leonv\Documents\Transporte\venv\lib\site-packages\werkzeug\local.py", line 347, in __getattr__
    return getattr(self._get_current_object(), name)
AttributeError: 'Usuario' object has no attribute 'usuario_aluno'
2022-11-14 11:01:33,794 INFO: Transporte inicialização [in C:\Users\leonv\Documents\Transporte\app\__init__.py:84]
