2022-11-14 11:55:26,102 ERROR: Exception on /alterar [GET] [in C:\Users\leonv\Documents\Transporte\venv\lib\site-packages\flask\app.py:1891]
Traceback (most recent call last):
  File "C:\Users\leonv\Documents\Transporte\venv\lib\site-packages\flask\app.py", line 2447, in wsgi_app
    response = self.full_dispatch_request()
  File "C:\Users\leonv\Documents\Transporte\venv\lib\site-packages\flask\app.py", line 1952, in full_dispatch_request
    rv = self.handle_user_exception(e)
  File "C:\Users\leonv\Documents\Transporte\venv\lib\site-packages\flask\app.py", line 1821, in handle_user_exception
    reraise(exc_type, exc_value, tb)
  File "C:\Users\leonv\Documents\Transporte\venv\lib\site-packages\flask\_compat.py", line 39, in reraise
    raise value
  File "C:\Users\leonv\Documents\Transporte\venv\lib\site-packages\flask\app.py", line 1950, in full_dispatch_request
    rv = self.dispatch_request()
  File "C:\Users\leonv\Documents\Transporte\venv\lib\site-packages\flask\app.py", line 1936, in dispatch_request
    return self.view_functions[rule.endpoint](**req.view_args)
  File "C:\Users\leonv\Documents\Transporte\venv\lib\site-packages\flask_login\utils.py", line 272, in decorated_view
    return func(*args, **kwargs)
  File "C:\Users\leonv\Documents\Transporte\app\main\routes.py", line 51, in alterar
    rotadia.confirmados.remove(aluno)
  File "C:\Users\leonv\Documents\Transporte\venv\lib\site-packages\sqlalchemy\orm\collections.py", line 1123, in remove
    fn(self, value)
ValueError: list.remove(x): x not in list
2022-11-14 11:57:51,221 INFO: Transporte inicialização [in C:\Users\leonv\Documents\Transporte\app\__init__.py:84]
2022-11-14 11:58:27,194 ERROR: Exception on /alterar [GET] [in C:\Users\leonv\Documents\Transporte\venv\lib\site-packages\flask\app.py:1891]
Traceback (most recent call last):
  File "C:\Users\leonv\Documents\Transporte\venv\lib\site-packages\flask\app.py", line 2447, in wsgi_app
    response = self.full_dispatch_request()
  File "C:\Users\leonv\Documents\Transporte\venv\lib\site-packages\flask\app.py", line 1952, in full_dispatch_request
    rv = self.handle_user_exception(e)
  File "C:\Users\leonv\Documents\Transporte\venv\lib\site-packages\flask\app.py", line 1821, in handle_user_exception
    reraise(exc_type, exc_value, tb)
  File "C:\Users\leonv\Documents\Transporte\venv\lib\site-packages\flask\_compat.py", line 39, in reraise
    raise value
  File "C:\Users\leonv\Documents\Transporte\venv\lib\site-packages\flask\app.py", line 1950, in full_dispatch_request
    rv = self.dispatch_request()
  File "C:\Users\leonv\Documents\Transporte\venv\lib\site-packages\flask\app.py", line 1936, in dispatch_request
    return self.view_functions[rule.endpoint](**req.view_args)
  File "C:\Users\leonv\Documents\Transporte\venv\lib\site-packages\flask_login\utils.py", line 272, in decorated_view
    return func(*args, **kwargs)
  File "C:\Users\leonv\Documents\Transporte\app\main\routes.py", line 54, in alterar
    rotadia.confirmados.remove(aluno)
  File "C:\Users\leonv\Documents\Transporte\venv\lib\site-packages\sqlalchemy\orm\collections.py", line 1123, in remove
    fn(self, value)
ValueError: list.remove(x): x not in list
2022-11-14 12:04:08,053 ERROR: Exception on /alterar [GET] [in C:\Users\leonv\Documents\Transporte\venv\lib\site-packages\flask\app.py:1891]
Traceback (most recent call last):
  File "C:\Users\leonv\Documents\Transporte\venv\lib\site-packages\flask\app.py", line 2447, in wsgi_app
    response = self.full_dispatch_request()
  File "C:\Users\leonv\Documents\Transporte\venv\lib\site-packages\flask\app.py", line 1952, in full_dispatch_request
    rv = self.handle_user_exception(e)
  File "C:\Users\leonv\Documents\Transporte\venv\lib\site-packages\flask\app.py", line 1821, in handle_user_exception
    reraise(exc_type, exc_value, tb)
  File "C:\Users\leonv\Documents\Transporte\venv\lib\site-packages\flask\_compat.py", line 39, in reraise
    raise value
  File "C:\Users\leonv\Documents\Transporte\venv\lib\site-packages\flask\app.py", line 1950, in full_dispatch_request
    rv = self.dispatch_request()
  File "C:\Users\leonv\Documents\Transporte\venv\lib\site-packages\flask\app.py", line 1936, in dispatch_request
    return self.view_functions[rule.endpoint](**req.view_args)
  File "C:\Users\leonv\Documents\Transporte\venv\lib\site-packages\flask_login\utils.py", line 272, in decorated_view
    return func(*args, **kwargs)
  File "C:\Users\leonv\Documents\Transporte\app\main\routes.py", line 54, in alterar
    rotadia.confirmados.remove(aluno)
  File "C:\Users\leonv\Documents\Transporte\venv\lib\site-packages\sqlalchemy\orm\collections.py", line 1123, in remove
    fn(self, value)
ValueError: list.remove(x): x not in list
2022-11-14 12:10:21,024 ERROR: Exception on /alterar [GET] [in C:\Users\leonv\Documents\Transporte\venv\lib\site-packages\flask\app.py:1891]
Traceback (most recent call last):
  File "C:\Users\leonv\Documents\Transporte\venv\lib\site-packages\flask\app.py", line 2447, in wsgi_app
    response = self.full_dispatch_request()
  File "C:\Users\leonv\Documents\Transporte\venv\lib\site-packages\flask\app.py", line 1952, in full_dispatch_request
    rv = self.handle_user_exception(e)
  File "C:\Users\leonv\Documents\Transporte\venv\lib\site-packages\flask\app.py", line 1821, in handle_user_exception
    reraise(exc_type, exc_value, tb)
  File "C:\Users\leonv\Documents\Transporte\venv\lib\site-packages\flask\_compat.py", line 39, in reraise
    raise value
  File "C:\Users\leonv\Documents\Transporte\venv\lib\site-packages\flask\app.py", line 1950, in full_dispatch_request
    rv = self.dispatch_request()
  File "C:\Users\leonv\Documents\Transporte\venv\lib\site-packages\flask\app.py", line 1936, in dispatch_request
    return self.view_functions[rule.endpoint](**req.view_args)
  File "C:\Users\leonv\Documents\Transporte\venv\lib\site-packages\flask_login\utils.py", line 272, in decorated_view
    return func(*args, **kwargs)
  File "C:\Users\leonv\Documents\Transporte\app\main\routes.py", line 52, in alterar
    rotadia.confirmados.add(aluno)
AttributeError: 'InstrumentedList' object has no attribute 'add'
2022-11-14 12:10:48,981 ERROR: Exception on /alterar [GET] [in C:\Users\leonv\Documents\Transporte\venv\lib\site-packages\flask\app.py:1891]
Traceback (most recent call last):
  File "C:\Users\leonv\Documents\Transporte\venv\lib\site-packages\flask\app.py", line 2447, in wsgi_app
    response = self.full_dispatch_request()
  File "C:\Users\leonv\Documents\Transporte\venv\lib\site-packages\flask\app.py", line 1952, in full_dispatch_request
    rv = self.handle_user_exception(e)
  File "C:\Users\leonv\Documents\Transporte\venv\lib\site-packages\flask\app.py", line 1821, in handle_user_exception
    reraise(exc_type, exc_value, tb)
  File "C:\Users\leonv\Documents\Transporte\venv\lib\site-packages\flask\_compat.py", line 39, in reraise
    raise value
  File "C:\Users\leonv\Documents\Transporte\venv\lib\site-packages\flask\app.py", line 1950, in full_dispatch_request
    rv = self.dispatch_request()
  File "C:\Users\leonv\Documents\Transporte\venv\lib\site-packages\flask\app.py", line 1936, in dispatch_request
    return self.view_functions[rule.endpoint](**req.view_args)
  File "C:\Users\leonv\Documents\Transporte\venv\lib\site-packages\flask_login\utils.py", line 272, in decorated_view
    return func(*args, **kwargs)
  File "C:\Users\leonv\Documents\Transporte\app\main\routes.py", line 52, in alterar
    rotadia.confirmados.append(aluno)
AttributeError: 'InstrumentedList' object has no attribute 'add'
2022-11-14 12:10:56,361 INFO: Transporte inicialização [in C:\Users\leonv\Documents\Transporte\app\__init__.py:84]
2022-11-14 12:18:41,021 INFO: Transporte inicialização [in C:\Users\leonv\Documents\Transporte\app\__init__.py:84]
2022-11-14 12:52:20,170 INFO: Transporte inicialização [in C:\Users\leonv\Documents\Transporte\app\__init__.py:84]
